<?xml version="1.0" encoding="utf-8"?>
<robot xmlns:xacro="http://www.ros.org/wiki/xacro" name="arm">

  <link
    name="base_link">
    <inertial>
      <origin
        xyz="-3.7491E-18 -2.2788E-19 0.03299"
        rpy="0 0 0" />
      <mass
        value="0.52527" />
      <inertia
        ixx="0.00053943"
        ixy="8.6574E-20"
        ixz="7.3971E-21"
        iyy="0.00053943"
        iyz="1.378E-21"
        izz="0.00066837" />
    </inertial>
    <visual>
      <origin
        xyz="0 0 0"
        rpy="0 0 0" />
      <geometry>
        <mesh
          filename="file://$(find armv1)/meshes/base_link.STL" />
      </geometry>
      <material
        name="">
        <color
          rgba="0.79216 0.81961 0.93333 1" />
      </material>
    </visual>
    <collision>
      <origin
        xyz="0 0 0"
        rpy="0 0 0" />
      <geometry>
        <mesh
          filename="file://$(find armv1)/meshes/base_link.STL" />
      </geometry>
    </collision>
  </link>
  <link
    name="link_1">
    <inertial>
      <origin
        xyz="0.00071426 -3.2376E-18 -0.15314"
        rpy="0 0 0" />
      <mass
        value="1.3745" />
      <inertia
        ixx="0.025151"
        ixy="3.4326E-20"
        ixz="-0.00011107"
        iyy="0.025197"
        iyz="-5.097E-19"
        izz="0.0011473" />
    </inertial>
    <visual>
      <origin
        xyz="0 0 0"
        rpy="0 0 0" />
      <geometry>
        <mesh
          filename="file://$(find armv1)/meshes/link_1.STL" />
      </geometry>
      <material
        name="">
        <color
          rgba="0.79216 0.81961 0.93333 1" />
      </material>
    </visual>
    <collision>
      <origin
        xyz="0 0 0"
        rpy="0 0 0" />
      <geometry>
        <mesh
          filename="file://$(find armv1)/meshes/link_1.STL" />
      </geometry>
    </collision>
  </link>
  <joint
    name="joint_1"
    type="revolute">
    <origin
      xyz="0 0 0.52"
      rpy="0 0 0" />
    <parent
      link="base_link" />
    <child
      link="link_1" />
    <axis
      xyz="0 0 1" />
    <limit
      lower="-3.142"
      upper="3.142"
      effort="200"
      velocity="3" />
  </joint>
  <link
    name="link_2">
    <inertial>
      <origin
        xyz="-0.10922 0.0020778 0"
        rpy="0 0 0" />
      <mass
        value="0.75598" />
      <inertia
        ixx="0.0013615"
        ixy="3.2638E-05"
        ixz="-4.6781E-20"
        iyy="0.0014547"
        iyz="1.079E-20"
        izz="0.0024247" />
    </inertial>
    <visual>
      <origin
        xyz="0 0 0"
        rpy="0 0 0" />
      <geometry>
        <mesh
          filename="file://$(find armv1)/meshes/link_2.STL" />
      </geometry>
      <material
        name="">
        <color
          rgba="0.79216 0.81961 0.93333 1" />
      </material>
    </visual>
    <collision>
      <origin
        xyz="0 0 0"
        rpy="0 0 0" />
      <geometry>
        <mesh
          filename="file://$(find armv1)/meshes/link_2.STL" />
      </geometry>
    </collision>
  </link>
  <joint
    name="joint_2"
    type="revolute">
    <origin
      xyz="0.055 0 -0.04"
      rpy="3.1416 0 3.1416" />
    <parent
      link="link_1" />
    <child
      link="link_2" />
    <axis
      xyz="-1 0 0" />
    <limit
      lower="-3.142"
      upper="3.142"
      effort="200"
      velocity="3" />
  </joint>
  <link
    name="link_3">
    <inertial>
      <origin
        xyz="0.00081217 0.45995 0"
        rpy="0 0 0" />
      <mass
        value="1.9341" />
      <inertia
        ixx="0.1141"
        ixy="-0.00042419"
        ixz="-2.3816E-19"
        iyy="0.0017316"
        iyz="2.3442E-18"
        izz="0.11507" />
    </inertial>
    <visual>
      <origin
        xyz="0 0 0"
        rpy="0 0 0" />
      <geometry>
        <mesh
          filename="file://$(find armv1)/meshes/link_3.STL" />
      </geometry>
      <material
        name="">
        <color
          rgba="0.79216 0.81961 0.93333 1" />
      </material>
    </visual>
    <collision>
      <origin
        xyz="0 0 0"
        rpy="0 0 0" />
      <geometry>
        <mesh
          filename="file://$(find armv1)/meshes/link_3.STL" />
      </geometry>
    </collision>
  </link>
  <joint
    name="joint_3"
    type="revolute">
    <origin
      xyz="-0.13 0.085 0"
      rpy="3.1416 0 3.1416" />
    <parent
      link="link_2" />
    <child
      link="link_3" />
    <axis
      xyz="0 -1 0" />
    <limit
      lower="-3.142"
      upper="3.14"
      effort="200"
      velocity="3" />
  </joint>
  <link
    name="link_4">
    <inertial>
      <origin
        xyz="0.069722 -0.00026601 -0.32967"
        rpy="0 0 0" />
      <mass
        value="0.93004" />
      <inertia
        ixx="0.080357"
        ixy="1.3058E-06"
        ixz="0.0016183"
        iyy="0.080543"
        iyz="-0.00010523"
        izz="0.00048779" />
    </inertial>
    <visual>
      <origin
        xyz="0 0 0"
        rpy="0 0 0" />
      <geometry>
        <mesh
          filename="file://$(find armv1)/meshes/link_4.STL" />
      </geometry>
      <material
        name="">
        <color
          rgba="0.79216 0.81961 0.93333 1" />
      </material>
    </visual>
    <collision>
      <origin
        xyz="0 0 0"
        rpy="0 0 0" />
      <geometry>
        <mesh
          filename="file://$(find armv1)/meshes/link_4.STL" />
      </geometry>
    </collision>
  </link>
  <joint
    name="joint_4"
    type="revolute">
    <origin
      xyz="0.085 0.73 0"
      rpy="0 0 0" />
    <parent
      link="link_3" />
    <child
      link="link_4" />
    <axis
      xyz="1 0 0" />
    <limit
      lower="-3.142"
      upper="3.142"
      effort="150"
      velocity="3" />
  </joint>
  <link
    name="link_5">
    <inertial>
      <origin
        xyz="5.5511E-17 -0.031616 0"
        rpy="0 0 0" />
      <mass
        value="0.045343" />
      <inertia
        ixx="1.6783E-05"
        ixy="7.0687E-21"
        ixz="-1.3861E-22"
        iyy="6.3927E-06"
        iyz="-5.0175E-22"
        izz="1.8533E-05" />
    </inertial>
    <visual>
      <origin
        xyz="0 0 0"
        rpy="0 0 0" />
      <geometry>
        <mesh
          filename="file://$(find armv1)/meshes/link_5.STL" />
      </geometry>
      <material
        name="">
        <color
          rgba="0.79216 0.81961 0.93333 1" />
      </material>
    </visual>
    <collision>
      <origin
        xyz="0 0 0"
        rpy="0 0 0" />
      <geometry>
        <mesh
          filename="file://$(find armv1)/meshes/link_5.STL" />
      </geometry>
    </collision>
  </link>
  <joint
    name="joint_5"
    type="revolute">
    <origin
      xyz="0.075 -0.04 -0.755"
      rpy="0 0 0" />
    <parent
      link="link_4" />
    <child
      link="link_5" />
    <axis
      xyz="0 -1 0" />
    <limit
      lower="-3.142"
      upper="3.14"
      effort="100"
      velocity="3" />
  </joint>
  
<ros2_control name="GazeboSystem" type="system">
  <hardware>
    <plugin>gazebo_ros2_control/GazeboSystem</plugin>
  </hardware>
  <joint name="joint_1">
    <command_interface name="position">
      <param name="min">-3.14</param>
      <param name="max">3.14</param>
    </command_interface>
    <state_interface name="position"/>
    <state_interface name="velocity"/>
  </joint>
  <joint name="joint_2">
    <command_interface name="position">
      <param name="min">-3.14</param>
      <param name="max">3.14</param>
    </command_interface>
    <state_interface name="position"/>
    <state_interface name="velocity"/>
  </joint>
  <joint name="joint_3">
    <command_interface name="position">
      <param name="min">-3.14</param>
      <param name="max">3.14</param>
    </command_interface>
    <state_interface name="position"/>
    <state_interface name="velocity"/>
  </joint>
  <joint name="joint_4">
    <command_interface name="position">
      <param name="min">-3.14</param>
      <param name="max">3.14</param>
    </command_interface>
    <state_interface name="position"/>
    <state_interface name="velocity"/>
  </joint>
  <joint name="joint_5">
    <command_interface name="position">
      <param name="min">-3.14</param>
      <param name="max">3.14</param>
    </command_interface>
    <state_interface name="position"/>
    <state_interface name="velocity"/>
  </joint>
</ros2_control>

<gazebo>
  <plugin filename="libgazebo_ros2_control.so" name="gazebo_ros2_control">
    <parameters>$(find armv1)/config/moveit_controller.yaml</parameters>
    <joint_controller>
      <joint name="joint_1">
        <controller>joint_trajectory_controller</controller>
      </joint>
      <joint name="joint_2">
        <controller>joint_trajectory_controller</controller>
      </joint>
      <joint name="joint_3">
        <controller>joint_trajectory_controller</controller>
      </joint>
      <joint name="joint_4">
        <controller>joint_trajectory_controller</controller>
      </joint>
      <joint name="joint_5">
        <controller>joint_trajectory_controller</controller>
      </joint>
    </joint_controller>
    <joint_state_broadcaster>
      <joint name="joint_1" />
      <joint name="joint_2" />
      <joint name="joint_3" />
      <joint name="joint_4" />
      <joint name="joint_5" />
    </joint_state_broadcaster>
  </plugin>
</gazebo>
</robot>