<?xml version="1.0" encoding="utf-8"?>
<!-- This URDF was automatically created by SolidWorks to URDF Exporter! Originally created by Stephen Brawner (brawner@gmail.com) 
     Commit Version: 1.6.0-4-g7f85cfe  Build Version: 1.6.7995.38578
     For more information, please see http://wiki.ros.org/sw_urdf_exporter -->
<robot xmlns:xacro="http://www.ros.org/wiki/xacro" name="arm">
  <link
    name="base_link">
    <inertial>
      <origin
        xyz="-3.7491E-18 -2.2788E-19 0.03299"
        rpy="0 0 0" />
      <mass
        value="0.52527" />
      <inertia
        ixx="0.00053943"
        ixy="8.6574E-20"
        ixz="7.3971E-21"
        iyy="0.00053943"
        iyz="1.378E-21"
        izz="0.00066837" />
    </inertial>
    <visual>
      <origin
        xyz="0 0 0"
        rpy="0 0 0" />
      <geometry>
        <mesh
          filename="package://armv1/meshes/base_link.STL" />
      </geometry>
      <material
        name="">
        <color
          rgba="0.79216 0.81961 0.93333 1" />
      </material>
    </visual>
    <collision>
      <origin
        xyz="0 0 0"
        rpy="0 0 0" />
      <geometry>
        <mesh
          filename="package://armv1/meshes/base_link.STL" />
      </geometry>
    </collision>
  </link>
  <link
    name="link_1">
    <inertial>
      <origin
        xyz="0.00071426 -3.2376E-18 -0.15314"
        rpy="0 0 0" />
      <mass
        value="1.3745" />
      <inertia
        ixx="0.025151"
        ixy="3.4326E-20"
        ixz="-0.00011107"
        iyy="0.025197"
        iyz="-5.097E-19"
        izz="0.0011473" />
    </inertial>
    <visual>
      <origin
        xyz="0 0 0"
        rpy="0 0 0" />
      <geometry>
        <mesh
          filename="package://armv1/meshes/link_1.STL" />
      </geometry>
      <material
        name="">
        <color
          rgba="0.79216 0.81961 0.93333 1" />
      </material>
    </visual>
    <collision>
      <origin
        xyz="0 0 0"
        rpy="0 0 0" />
      <geometry>
        <mesh
          filename="package://armv1/meshes/link_1.STL" />
      </geometry>
    </collision>
  </link>
  <joint
    name="joint_1"
    type="revolute">
    <origin
      xyz="0 0 0.52"
      rpy="0 0 0" />
    <parent
      link="base_link" />
    <child
      link="link_1" />
    <axis
      xyz="0 0 1" />
    <limit
      lower="-3.142"
      upper="3.142"
      effort="200"
      velocity="3" />
  </joint>
  <link
    name="link_2">
    <inertial>
      <origin
        xyz="-0.10922 0.0020778 0"
        rpy="0 0 0" />
      <mass
        value="0.75598" />
      <inertia
        ixx="0.0013615"
        ixy="3.2638E-05"
        ixz="-4.6781E-20"
        iyy="0.0014547"
        iyz="1.079E-20"
        izz="0.0024247" />
    </inertial>
    <visual>
      <origin
        xyz="0 0 0"
        rpy="0 0 0" />
      <geometry>
        <mesh
          filename="package://armv1/meshes/link_2.STL" />
      </geometry>
      <material
        name="">
        <color
          rgba="0.79216 0.81961 0.93333 1" />
      </material>
    </visual>
    <collision>
      <origin
        xyz="0 0 0"
        rpy="0 0 0" />
      <geometry>
        <mesh
          filename="package://armv1/meshes/link_2.STL" />
      </geometry>
    </collision>
  </link>
  <joint
    name="joint_2"
    type="revolute">
    <origin
      xyz="0.055 0 -0.04"
      rpy="3.1416 0 3.1416" />
    <parent
      link="link_1" />
    <child
      link="link_2" />
    <axis
      xyz="-1 0 0" />
    <limit
      lower="-3.142"
      upper="3.142"
      effort="200"
      velocity="3" />
  </joint>
  <link
    name="link_3">
    <inertial>
      <origin
        xyz="0.00081217 0.45995 0"
        rpy="0 0 0" />
      <mass
        value="1.9341" />
      <inertia
        ixx="0.1141"
        ixy="-0.00042419"
        ixz="-2.3816E-19"
        iyy="0.0017316"
        iyz="2.3442E-18"
        izz="0.11507" />
    </inertial>
    <visual>
      <origin
        xyz="0 0 0"
        rpy="0 0 0" />
      <geometry>
        <mesh
          filename="package://armv1/meshes/link_3.STL" />
      </geometry>
      <material
        name="">
        <color
          rgba="0.79216 0.81961 0.93333 1" />
      </material>
    </visual>
    <collision>
      <origin
        xyz="0 0 0"
        rpy="0 0 0" />
      <geometry>
        <mesh
          filename="package://armv1/meshes/link_3.STL" />
      </geometry>
    </collision>
  </link>
  <joint
    name="joint_3"
    type="revolute">
    <origin
      xyz="-0.13 0.085 0"
      rpy="3.1416 0 3.1416" />
    <parent
      link="link_2" />
    <child
      link="link_3" />
    <axis
      xyz="0 -1 0" />
    <limit
      lower="-3.142"
      upper="3.14"
      effort="200"
      velocity="3" />
  </joint>
  <link
    name="link_4">
    <inertial>
      <origin
        xyz="0.069722 -0.00026601 -0.32967"
        rpy="0 0 0" />
      <mass
        value="0.93004" />
      <inertia
        ixx="0.080357"
        ixy="1.3058E-06"
        ixz="0.0016183"
        iyy="0.080543"
        iyz="-0.00010523"
        izz="0.00048779" />
    </inertial>
    <visual>
      <origin
        xyz="0 0 0"
        rpy="0 0 0" />
      <geometry>
        <mesh
          filename="package://armv1/meshes/link_4.STL" />
      </geometry>
      <material
        name="">
        <color
          rgba="0.79216 0.81961 0.93333 1" />
      </material>
    </visual>
    <collision>
      <origin
        xyz="0 0 0"
        rpy="0 0 0" />
      <geometry>
        <mesh
          filename="package://armv1/meshes/link_4.STL" />
      </geometry>
    </collision>
  </link>
  <joint
    name="joint_4"
    type="revolute">
    <origin
      xyz="0.085 0.73 0"
      rpy="0 0 0" />
    <parent
      link="link_3" />
    <child
      link="link_4" />
    <axis
      xyz="1 0 0" />
    <limit
      lower="-3.142"
      upper="3.142"
      effort="150"
      velocity="3" />
  </joint>
  <link
    name="link_5">
    <inertial>
      <origin
        xyz="5.5511E-17 -0.031616 0"
        rpy="0 0 0" />
      <mass
        value="0.045343" />
      <inertia
        ixx="1.6783E-05"
        ixy="7.0687E-21"
        ixz="-1.3861E-22"
        iyy="6.3927E-06"
        iyz="-5.0175E-22"
        izz="1.8533E-05" />
    </inertial>
    <visual>
      <origin
        xyz="0 0 0"
        rpy="0 0 0" />
      <geometry>
        <mesh
          filename="package://armv1/meshes/link_5.STL" />
      </geometry>
      <material
        name="">
        <color
          rgba="0.79216 0.81961 0.93333 1" />
      </material>
    </visual>
    <collision>
      <origin
        xyz="0 0 0"
        rpy="0 0 0" />
      <geometry>
        <mesh
          filename="package://armv1/meshes/link_5.STL" />
      </geometry>
    </collision>
  </link>
  <joint
    name="joint_5"
    type="revolute">
    <origin
      xyz="0.075 -0.04 -0.755"
      rpy="0 0 0" />
    <parent
      link="link_4" />
    <child
      link="link_5" />
    <axis
      xyz="0 -1 0" />
    <limit
      lower="-3.142"
      upper="3.14"
      effort="100"
      velocity="3" />
  </joint>

<xacro:include filename="arm.gazebo.xacro"/>

<xacro:transmission name="trans_base_link1" joint_name="joint_1" actuator_name="motor_base_link_link1"/>

<xacro:transmission name="trans_link1_link2" joint_name="joint_2" actuator_name="motor_link1_link2"/>

<xacro:transmission name="trans_link2_link3" joint_name="joint_3" actuator_name="motor_link2_link3"/>

<xacro:transmission name="trans_link3_link4" joint_name="joint_4" actuator_name="motor_link3_link4"/>

<xacro:transmission name="trans_link4_link5" joint_name="joint_5" actuator_name="motor_link4_link5"/>

</robot>